{
 "cells": [
  {
   "cell_type": "code",
   "execution_count": 1,
   "metadata": {},
   "outputs": [],
   "source": [
    "from SagasuSubs import utils,models,patch\n",
    "from pathlib import Path\n",
    "\n",
    "patch.patch()"
   ]
  },
  {
   "cell_type": "code",
   "execution_count": 2,
   "metadata": {},
   "outputs": [
    {
     "data": {
      "text/plain": [
       "[PosixPath('subtitles/subs_list/animation/1970/(1970.4.1)明日之丈 第1季/BD/冷番补完字幕组/[冷番补完][明日之丈][あしたのジョー][01][480P][简体外挂].ass'),\n",
       " PosixPath('subtitles/subs_list/animation/1970/(1970.4.1)明日之丈 第1季/BD/冷番补完字幕组/[冷番补完][明日之丈][あしたのジョー][02][480P][简体外挂].ass'),\n",
       " PosixPath('subtitles/subs_list/animation/1970/(1970.4.1)明日之丈 第1季/BD/冷番补完字幕组/[冷番补完][明日之丈][あしたのジョー][03][480P][简体外挂].ass'),\n",
       " PosixPath('subtitles/subs_list/animation/1970/(1970.4.1)明日之丈 第1季/BD/冷番补完字幕组/[冷番补完][明日之丈][あしたのジョー][04][480P][简体外挂].ass'),\n",
       " PosixPath('subtitles/subs_list/animation/1970/(1970.4.1)明日之丈 第1季/BD/冷番补完字幕组/[冷番补完][明日之丈][あしたのジョー][05][480P][简体外挂].ass')]"
      ]
     },
     "execution_count": 2,
     "metadata": {},
     "output_type": "execute_result"
    }
   ],
   "source": [
    "workdir = Path('.') / 'subtitles' / 'subs_list'\n",
    "\n",
    "files = [*utils.iterate_files(workdir,'.ass')]\n",
    "\n",
    "files[:5]"
   ]
  },
  {
   "cell_type": "code",
   "execution_count": 3,
   "metadata": {},
   "outputs": [
    {
     "name": "stderr",
     "output_type": "stream",
     "text": [
      "Traceback (most recent call last):\n",
      "  File \"/home/mix/Documents/SagasuSubs/.venv/lib/python3.9/site-packages/sqlalchemy/engine/default.py\", line 717, in do_execute\n",
      "    cursor.execute(statement, parameters)\n",
      "sqlite3.OperationalError: table files already exists\n",
      "\n",
      "The above exception was the direct cause of the following exception:\n",
      "\n",
      "Traceback (most recent call last):\n",
      "  File \"/home/mix/Documents/SagasuSubs/.venv/lib/python3.9/site-packages/sqlalchemy/engine/default.py\", line 717, in do_execute\n",
      "    cursor.execute(statement, parameters)\n",
      "sqlalchemy.exc.OperationalError: (sqlite3.OperationalError) table files already exists\n",
      "[SQL: \n",
      "CREATE TABLE files (\n",
      "\tid INTEGER NOT NULL, \n",
      "\tfilename VARCHAR(1024) NOT NULL, \n",
      "\tsha1 VARCHAR(40) NOT NULL, \n",
      "\tpath VARCHAR NOT NULL, \n",
      "\tseries_name VARCHAR, \n",
      "\tseries_id INTEGER, \n",
      "\tepisode_name VARCHAR, \n",
      "\tepisode_id INTEGER, \n",
      "\tPRIMARY KEY (id), \n",
      "\tFOREIGN KEY(series_id) REFERENCES series (id), \n",
      "\tFOREIGN KEY(episode_id) REFERENCES episode (id)\n",
      ")\n",
      "\n",
      "]\n",
      "(Background on this error at: https://sqlalche.me/e/14/e3q8)\n"
     ]
    }
   ],
   "source": [
    "from tqdm.notebook import tqdm\n",
    "from traceback import format_exc,print_exc\n",
    "import re\n",
    "\n",
    "from SagasuSubs.database import FileCrud,DialogCrud,dto\n",
    "\n",
    "DB_PATH = Path('.') / 'db.sqlite3'\n",
    "file_crud = FileCrud(DB_PATH)\n",
    "dialog_crud =DialogCrud(DB_PATH)\n",
    "\n",
    "\n",
    "try:\n",
    "    file_crud.create_table()\n",
    "    dialog_crud.create_table()\n",
    "except Exception as e:\n",
    "    print_exc(-1)\n",
    "\n",
    "PATH_REGEX = re.compile(\n",
    "    r'^.+/(?P<year>\\d+?)/\\((?P<date>[0-9.]+?)\\)(?P<name>.+?)/(?P<child_path>.+)$'\n",
    ")\n",
    "\n",
    "        \n",
    "    "
   ]
  },
  {
   "cell_type": "code",
   "execution_count": null,
   "metadata": {},
   "outputs": [
    {
     "data": {
      "application/vnd.jupyter.widget-view+json": {
       "model_id": "858b1c483a2e4d25803daf8e55d92cca",
       "version_major": 2,
       "version_minor": 0
      },
      "text/plain": [
       "  0%|          | 0/50231 [00:00<?, ?it/s]"
      ]
     },
     "metadata": {},
     "output_type": "display_data"
    },
    {
     "name": "stderr",
     "output_type": "stream",
     "text": [
      "/home/mix/Documents/SagasuSubs/SagasuSubs/patch.py:59: UserWarning: Failed to parse field f='encoding',v='1Style: Karaoke0' due to ValueError(\"invalid literal for int() with base 10: '1Style: Karaoke0'\"), fallback to None\n",
      "  warn(f\"Failed to parse field {f=!r},{v=!r} due to {e!r}, fallback to None\")\n",
      "/home/mix/Documents/SagasuSubs/SagasuSubs/patch.py:59: UserWarning: Failed to parse field f='start',v='0:00:00.-40' due to AttributeError(\"'NoneType' object has no attribute 'groups'\"), fallback to None\n",
      "  warn(f\"Failed to parse field {f=!r},{v=!r} due to {e!r}, fallback to None\")\n",
      "/home/mix/Documents/SagasuSubs/SagasuSubs/patch.py:59: UserWarning: Failed to parse field f='end',v='0:00:00.-40' due to AttributeError(\"'NoneType' object has no attribute 'groups'\"), fallback to None\n",
      "  warn(f\"Failed to parse field {f=!r},{v=!r} due to {e!r}, fallback to None\")\n",
      "/home/mix/Documents/SagasuSubs/SagasuSubs/patch.py:59: UserWarning: Failed to parse field f='marginv',v='' due to ValueError(\"invalid literal for int() with base 10: ''\"), fallback to None\n",
      "  warn(f\"Failed to parse field {f=!r},{v=!r} due to {e!r}, fallback to None\")\n",
      "/home/mix/Documents/SagasuSubs/SagasuSubs/patch.py:59: UserWarning: Failed to parse field f='start',v='0:00:-1.00' due to AttributeError(\"'NoneType' object has no attribute 'groups'\"), fallback to None\n",
      "  warn(f\"Failed to parse field {f=!r},{v=!r} due to {e!r}, fallback to None\")\n",
      "/home/mix/Documents/SagasuSubs/SagasuSubs/patch.py:59: UserWarning: Failed to parse field f='end',v='0:00:-1.00' due to AttributeError(\"'NoneType' object has no attribute 'groups'\"), fallback to None\n",
      "  warn(f\"Failed to parse field {f=!r},{v=!r} due to {e!r}, fallback to None\")\n",
      "/home/mix/Documents/SagasuSubs/SagasuSubs/patch.py:59: UserWarning: Failed to parse field f='start',v='0:00:-10.-50' due to AttributeError(\"'NoneType' object has no attribute 'groups'\"), fallback to None\n",
      "  warn(f\"Failed to parse field {f=!r},{v=!r} due to {e!r}, fallback to None\")\n",
      "/home/mix/Documents/SagasuSubs/SagasuSubs/patch.py:59: UserWarning: Failed to parse field f='end',v='0:00:-10.-50' due to AttributeError(\"'NoneType' object has no attribute 'groups'\"), fallback to None\n",
      "  warn(f\"Failed to parse field {f=!r},{v=!r} due to {e!r}, fallback to None\")\n",
      "/home/mix/Documents/SagasuSubs/SagasuSubs/patch.py:59: UserWarning: Failed to parse field f='start',v='0:00:-10.-10' due to AttributeError(\"'NoneType' object has no attribute 'groups'\"), fallback to None\n",
      "  warn(f\"Failed to parse field {f=!r},{v=!r} due to {e!r}, fallback to None\")\n",
      "/home/mix/Documents/SagasuSubs/SagasuSubs/patch.py:59: UserWarning: Failed to parse field f='end',v='0:00:-10.-10' due to AttributeError(\"'NoneType' object has no attribute 'groups'\"), fallback to None\n",
      "  warn(f\"Failed to parse field {f=!r},{v=!r} due to {e!r}, fallback to None\")\n",
      "/home/mix/Documents/SagasuSubs/SagasuSubs/patch.py:59: UserWarning: Failed to parse field f='start',v='0:00:00.-50' due to AttributeError(\"'NoneType' object has no attribute 'groups'\"), fallback to None\n",
      "  warn(f\"Failed to parse field {f=!r},{v=!r} due to {e!r}, fallback to None\")\n",
      "/home/mix/Documents/SagasuSubs/SagasuSubs/patch.py:59: UserWarning: Failed to parse field f='end',v='0:00:00.-50' due to AttributeError(\"'NoneType' object has no attribute 'groups'\"), fallback to None\n",
      "  warn(f\"Failed to parse field {f=!r},{v=!r} due to {e!r}, fallback to None\")\n",
      "/home/mix/Documents/SagasuSubs/SagasuSubs/patch.py:59: UserWarning: Failed to parse field f='start',v='0:00:-1.-5' due to AttributeError(\"'NoneType' object has no attribute 'groups'\"), fallback to None\n",
      "  warn(f\"Failed to parse field {f=!r},{v=!r} due to {e!r}, fallback to None\")\n",
      "/home/mix/Documents/SagasuSubs/SagasuSubs/patch.py:59: UserWarning: Failed to parse field f='end',v='0:00:-1.-5' due to AttributeError(\"'NoneType' object has no attribute 'groups'\"), fallback to None\n",
      "  warn(f\"Failed to parse field {f=!r},{v=!r} due to {e!r}, fallback to None\")\n",
      "/home/mix/Documents/SagasuSubs/SagasuSubs/patch.py:59: UserWarning: Failed to parse field f='start',v='0:00:-10.-5' due to AttributeError(\"'NoneType' object has no attribute 'groups'\"), fallback to None\n",
      "  warn(f\"Failed to parse field {f=!r},{v=!r} due to {e!r}, fallback to None\")\n",
      "/home/mix/Documents/SagasuSubs/SagasuSubs/patch.py:59: UserWarning: Failed to parse field f='end',v='0:00:-10.-5' due to AttributeError(\"'NoneType' object has no attribute 'groups'\"), fallback to None\n",
      "  warn(f\"Failed to parse field {f=!r},{v=!r} due to {e!r}, fallback to None\")\n",
      "/home/mix/Documents/SagasuSubs/SagasuSubs/patch.py:59: UserWarning: Failed to parse field f='start',v='0:00:00.-60' due to AttributeError(\"'NoneType' object has no attribute 'groups'\"), fallback to None\n",
      "  warn(f\"Failed to parse field {f=!r},{v=!r} due to {e!r}, fallback to None\")\n",
      "/home/mix/Documents/SagasuSubs/SagasuSubs/patch.py:59: UserWarning: Failed to parse field f='end',v='0:00:00.-60' due to AttributeError(\"'NoneType' object has no attribute 'groups'\"), fallback to None\n",
      "  warn(f\"Failed to parse field {f=!r},{v=!r} due to {e!r}, fallback to None\")\n",
      "/home/mix/Documents/SagasuSubs/SagasuSubs/patch.py:59: UserWarning: Failed to parse field f='start',v='0:00:-10.-55' due to AttributeError(\"'NoneType' object has no attribute 'groups'\"), fallback to None\n",
      "  warn(f\"Failed to parse field {f=!r},{v=!r} due to {e!r}, fallback to None\")\n",
      "/home/mix/Documents/SagasuSubs/SagasuSubs/patch.py:59: UserWarning: Failed to parse field f='end',v='0:00:-10.-55' due to AttributeError(\"'NoneType' object has no attribute 'groups'\"), fallback to None\n",
      "  warn(f\"Failed to parse field {f=!r},{v=!r} due to {e!r}, fallback to None\")\n",
      "/home/mix/Documents/SagasuSubs/SagasuSubs/patch.py:59: UserWarning: Failed to parse field f='start',v='0:00:00.-56' due to AttributeError(\"'NoneType' object has no attribute 'groups'\"), fallback to None\n",
      "  warn(f\"Failed to parse field {f=!r},{v=!r} due to {e!r}, fallback to None\")\n",
      "/home/mix/Documents/SagasuSubs/SagasuSubs/patch.py:59: UserWarning: Failed to parse field f='end',v='0:00:00.-56' due to AttributeError(\"'NoneType' object has no attribute 'groups'\"), fallback to None\n",
      "  warn(f\"Failed to parse field {f=!r},{v=!r} due to {e!r}, fallback to None\")\n",
      "/home/mix/Documents/SagasuSubs/SagasuSubs/patch.py:59: UserWarning: Failed to parse field f='start',v='0:00:00.-55' due to AttributeError(\"'NoneType' object has no attribute 'groups'\"), fallback to None\n",
      "  warn(f\"Failed to parse field {f=!r},{v=!r} due to {e!r}, fallback to None\")\n",
      "/home/mix/Documents/SagasuSubs/SagasuSubs/patch.py:59: UserWarning: Failed to parse field f='end',v='0:00:00.-55' due to AttributeError(\"'NoneType' object has no attribute 'groups'\"), fallback to None\n",
      "  warn(f\"Failed to parse field {f=!r},{v=!r} due to {e!r}, fallback to None\")\n"
     ]
    },
    {
     "name": "stdout",
     "output_type": "stream",
     "text": [
      "Error occurred during processing file subtitles/subs_list/animation/2008/(2008.4.6)绝对可怜CHILDREN/BD/[アニメ BD]/[アニメ BD] 絶対可憐チルドレン 第27話 「宣戦布告！パンドラからの挑戦状」.ass:\n",
      "-->\tTraceback (most recent call last):\n",
      "-->\t  File \"/tmp/ipykernel_34135/4174801234.py\", line 8, in <module>\n",
      "-->\t    data = models.SubtitlePersist.from_file(file,format='ass',exclude_fx=True)\n",
      "-->\t  File \"/home/mix/Documents/SagasuSubs/SagasuSubs/models.py\", line 62, in from_file\n",
      "-->\t    DialogContent(\n",
      "-->\t  File \"pydantic/main.py\", line 406, in pydantic.main.BaseModel.__init__\n",
      "-->\tpydantic.error_wrappers.ValidationError: 2 validation errors for DialogContent\n",
      "-->\tbegin\n",
      "-->\t  none is not an allowed value (type=type_error.none.not_allowed)\n",
      "-->\tend\n",
      "-->\t  none is not an allowed value (type=type_error.none.not_allowed)\n",
      "Error occurred during processing file subtitles/subs_list/animation/2008/(2008.4.6)绝对可怜CHILDREN/BD/[アニメ BD]/[アニメ BD] 絶対可憐チルドレン 第28話 「羞月閉花！蕾見チュー意報」.ass:\n",
      "-->\tTraceback (most recent call last):\n",
      "-->\t  File \"/tmp/ipykernel_34135/4174801234.py\", line 8, in <module>\n",
      "-->\t    data = models.SubtitlePersist.from_file(file,format='ass',exclude_fx=True)\n",
      "-->\t  File \"/home/mix/Documents/SagasuSubs/SagasuSubs/models.py\", line 62, in from_file\n",
      "-->\t    DialogContent(\n",
      "-->\t  File \"pydantic/main.py\", line 406, in pydantic.main.BaseModel.__init__\n",
      "-->\tpydantic.error_wrappers.ValidationError: 2 validation errors for DialogContent\n",
      "-->\tbegin\n",
      "-->\t  none is not an allowed value (type=type_error.none.not_allowed)\n",
      "-->\tend\n",
      "-->\t  none is not an allowed value (type=type_error.none.not_allowed)\n",
      "Error occurred during processing file subtitles/subs_list/animation/2008/(2008.4.6)绝对可怜CHILDREN/BD/[アニメ BD]/[アニメ BD] 絶対可憐チルドレン 第30話 「呉越同舟！ご金庫破りは計画的に」.ass:\n",
      "-->\tTraceback (most recent call last):\n",
      "-->\t  File \"/tmp/ipykernel_34135/4174801234.py\", line 8, in <module>\n",
      "-->\t    data = models.SubtitlePersist.from_file(file,format='ass',exclude_fx=True)\n",
      "-->\t  File \"/home/mix/Documents/SagasuSubs/SagasuSubs/models.py\", line 62, in from_file\n",
      "-->\t    DialogContent(\n",
      "-->\t  File \"pydantic/main.py\", line 406, in pydantic.main.BaseModel.__init__\n",
      "-->\tpydantic.error_wrappers.ValidationError: 2 validation errors for DialogContent\n",
      "-->\tbegin\n",
      "-->\t  none is not an allowed value (type=type_error.none.not_allowed)\n",
      "-->\tend\n",
      "-->\t  none is not an allowed value (type=type_error.none.not_allowed)\n",
      "Error occurred during processing file subtitles/subs_list/animation/2008/(2008.4.6)绝对可怜CHILDREN/BD/[アニメ BD]/[アニメ BD] 絶対可憐チルドレン 第32話 「珍味佳肴！タッチ·ミー·イフ·ユー·キャン」.ass:\n",
      "-->\tTraceback (most recent call last):\n",
      "-->\t  File \"/tmp/ipykernel_34135/4174801234.py\", line 8, in <module>\n",
      "-->\t    data = models.SubtitlePersist.from_file(file,format='ass',exclude_fx=True)\n",
      "-->\t  File \"/home/mix/Documents/SagasuSubs/SagasuSubs/models.py\", line 62, in from_file\n",
      "-->\t    DialogContent(\n",
      "-->\t  File \"pydantic/main.py\", line 406, in pydantic.main.BaseModel.__init__\n",
      "-->\tpydantic.error_wrappers.ValidationError: 2 validation errors for DialogContent\n",
      "-->\tbegin\n",
      "-->\t  none is not an allowed value (type=type_error.none.not_allowed)\n",
      "-->\tend\n",
      "-->\t  none is not an allowed value (type=type_error.none.not_allowed)\n",
      "Error occurred during processing file subtitles/subs_list/animation/2008/(2008.4.6)绝对可怜CHILDREN/BD/[アニメ BD]/[アニメ BD] 絶対可憐チルドレン 第34話 「朝蠅暮蚊！皆本が手をする足をする！？」.ass:\n",
      "-->\tTraceback (most recent call last):\n",
      "-->\t  File \"/tmp/ipykernel_34135/4174801234.py\", line 8, in <module>\n",
      "-->\t    data = models.SubtitlePersist.from_file(file,format='ass',exclude_fx=True)\n",
      "-->\t  File \"/home/mix/Documents/SagasuSubs/SagasuSubs/models.py\", line 62, in from_file\n",
      "-->\t    DialogContent(\n",
      "-->\t  File \"pydantic/main.py\", line 406, in pydantic.main.BaseModel.__init__\n",
      "-->\tpydantic.error_wrappers.ValidationError: 2 validation errors for DialogContent\n",
      "-->\tbegin\n",
      "-->\t  none is not an allowed value (type=type_error.none.not_allowed)\n",
      "-->\tend\n",
      "-->\t  none is not an allowed value (type=type_error.none.not_allowed)\n",
      "Error occurred during processing file subtitles/subs_list/animation/2008/(2008.4.6)绝对可怜CHILDREN/BD/[アニメ BD]/[アニメ BD] 絶対可憐チルドレン 第35話 「多情多恨！初音の家出」.ass:\n",
      "-->\tTraceback (most recent call last):\n",
      "-->\t  File \"/tmp/ipykernel_34135/4174801234.py\", line 8, in <module>\n",
      "-->\t    data = models.SubtitlePersist.from_file(file,format='ass',exclude_fx=True)\n",
      "-->\t  File \"/home/mix/Documents/SagasuSubs/SagasuSubs/models.py\", line 62, in from_file\n",
      "-->\t    DialogContent(\n",
      "-->\t  File \"pydantic/main.py\", line 406, in pydantic.main.BaseModel.__init__\n",
      "-->\tpydantic.error_wrappers.ValidationError: 2 validation errors for DialogContent\n",
      "-->\tbegin\n",
      "-->\t  none is not an allowed value (type=type_error.none.not_allowed)\n",
      "-->\tend\n",
      "-->\t  none is not an allowed value (type=type_error.none.not_allowed)\n",
      "Error occurred during processing file subtitles/subs_list/animation/2008/(2008.4.6)绝对可怜CHILDREN/BD/[アニメ BD]/[アニメ BD] 絶対可憐チルドレン 第37話 「強敵来襲！ブラック·ファントム」.ass:\n",
      "-->\tTraceback (most recent call last):\n",
      "-->\t  File \"/tmp/ipykernel_34135/4174801234.py\", line 8, in <module>\n",
      "-->\t    data = models.SubtitlePersist.from_file(file,format='ass',exclude_fx=True)\n",
      "-->\t  File \"/home/mix/Documents/SagasuSubs/SagasuSubs/models.py\", line 62, in from_file\n",
      "-->\t    DialogContent(\n",
      "-->\t  File \"pydantic/main.py\", line 406, in pydantic.main.BaseModel.__init__\n",
      "-->\tpydantic.error_wrappers.ValidationError: 2 validation errors for DialogContent\n",
      "-->\tbegin\n",
      "-->\t  none is not an allowed value (type=type_error.none.not_allowed)\n",
      "-->\tend\n",
      "-->\t  none is not an allowed value (type=type_error.none.not_allowed)\n",
      "Error occurred during processing file subtitles/subs_list/animation/2008/(2008.4.6)绝对可怜CHILDREN/BD/[アニメ BD]/[アニメ BD] 絶対可憐チルドレン 第38話 「胡蝶之夢！ドリームメイカー」.ass:\n",
      "-->\tTraceback (most recent call last):\n",
      "-->\t  File \"/tmp/ipykernel_34135/4174801234.py\", line 8, in <module>\n",
      "-->\t    data = models.SubtitlePersist.from_file(file,format='ass',exclude_fx=True)\n",
      "-->\t  File \"/home/mix/Documents/SagasuSubs/SagasuSubs/models.py\", line 62, in from_file\n",
      "-->\t    DialogContent(\n",
      "-->\t  File \"pydantic/main.py\", line 406, in pydantic.main.BaseModel.__init__\n",
      "-->\tpydantic.error_wrappers.ValidationError: 2 validation errors for DialogContent\n",
      "-->\tbegin\n",
      "-->\t  none is not an allowed value (type=type_error.none.not_allowed)\n",
      "-->\tend\n",
      "-->\t  none is not an allowed value (type=type_error.none.not_allowed)\n",
      "Error occurred during processing file subtitles/subs_list/animation/2008/(2008.4.6)绝对可怜CHILDREN/BD/[アニメ BD]/[アニメ BD] 絶対可憐チルドレン 第39話 「夢幻泡影！サイコダイバーズ」.ass:\n",
      "-->\tTraceback (most recent call last):\n",
      "-->\t  File \"/tmp/ipykernel_34135/4174801234.py\", line 8, in <module>\n",
      "-->\t    data = models.SubtitlePersist.from_file(file,format='ass',exclude_fx=True)\n",
      "-->\t  File \"/home/mix/Documents/SagasuSubs/SagasuSubs/models.py\", line 62, in from_file\n",
      "-->\t    DialogContent(\n",
      "-->\t  File \"pydantic/main.py\", line 406, in pydantic.main.BaseModel.__init__\n",
      "-->\tpydantic.error_wrappers.ValidationError: 2 validation errors for DialogContent\n",
      "-->\tbegin\n",
      "-->\t  none is not an allowed value (type=type_error.none.not_allowed)\n",
      "-->\tend\n",
      "-->\t  none is not an allowed value (type=type_error.none.not_allowed)\n",
      "Error occurred during processing file subtitles/subs_list/animation/2008/(2008.4.6)绝对可怜CHILDREN/BD/[アニメ BD]/[アニメ BD] 絶対可憐チルドレン 第40話 「蕾見山荘！突入せよ！」.ass:\n",
      "-->\tTraceback (most recent call last):\n",
      "-->\t  File \"/tmp/ipykernel_34135/4174801234.py\", line 8, in <module>\n",
      "-->\t    data = models.SubtitlePersist.from_file(file,format='ass',exclude_fx=True)\n",
      "-->\t  File \"/home/mix/Documents/SagasuSubs/SagasuSubs/models.py\", line 62, in from_file\n",
      "-->\t    DialogContent(\n",
      "-->\t  File \"pydantic/main.py\", line 406, in pydantic.main.BaseModel.__init__\n",
      "-->\tpydantic.error_wrappers.ValidationError: 2 validation errors for DialogContent\n",
      "-->\tbegin\n",
      "-->\t  none is not an allowed value (type=type_error.none.not_allowed)\n",
      "-->\tend\n",
      "-->\t  none is not an allowed value (type=type_error.none.not_allowed)\n",
      "Error occurred during processing file subtitles/subs_list/animation/2008/(2008.4.6)绝对可怜CHILDREN/BD/[アニメ BD]/[アニメ BD] 絶対可憐チルドレン 第41話 「比翼連理！国王陛下のチルドレン」.ass:\n",
      "-->\tTraceback (most recent call last):\n",
      "-->\t  File \"/tmp/ipykernel_34135/4174801234.py\", line 8, in <module>\n",
      "-->\t    data = models.SubtitlePersist.from_file(file,format='ass',exclude_fx=True)\n",
      "-->\t  File \"/home/mix/Documents/SagasuSubs/SagasuSubs/models.py\", line 62, in from_file\n",
      "-->\t    DialogContent(\n",
      "-->\t  File \"pydantic/main.py\", line 406, in pydantic.main.BaseModel.__init__\n",
      "-->\tpydantic.error_wrappers.ValidationError: 2 validation errors for DialogContent\n",
      "-->\tbegin\n",
      "-->\t  none is not an allowed value (type=type_error.none.not_allowed)\n",
      "-->\tend\n",
      "-->\t  none is not an allowed value (type=type_error.none.not_allowed)\n",
      "Error occurred during processing file subtitles/subs_list/animation/2008/(2008.4.6)绝对可怜CHILDREN/BD/[アニメ BD]/[アニメ BD] 絶対可憐チルドレン 第42話 「合体問題！ファンタスティック·トイ」.ass:\n",
      "-->\tTraceback (most recent call last):\n",
      "-->\t  File \"/tmp/ipykernel_34135/4174801234.py\", line 8, in <module>\n",
      "-->\t    data = models.SubtitlePersist.from_file(file,format='ass',exclude_fx=True)\n",
      "-->\t  File \"/home/mix/Documents/SagasuSubs/SagasuSubs/models.py\", line 62, in from_file\n",
      "-->\t    DialogContent(\n",
      "-->\t  File \"pydantic/main.py\", line 406, in pydantic.main.BaseModel.__init__\n",
      "-->\tpydantic.error_wrappers.ValidationError: 2 validation errors for DialogContent\n",
      "-->\tbegin\n",
      "-->\t  none is not an allowed value (type=type_error.none.not_allowed)\n",
      "-->\tend\n",
      "-->\t  none is not an allowed value (type=type_error.none.not_allowed)\n"
     ]
    },
    {
     "name": "stderr",
     "output_type": "stream",
     "text": [
      "/home/mix/Documents/SagasuSubs/SagasuSubs/patch.py:59: UserWarning: Failed to parse field f='start',v='0:00:-10.-60' due to AttributeError(\"'NoneType' object has no attribute 'groups'\"), fallback to None\n",
      "  warn(f\"Failed to parse field {f=!r},{v=!r} due to {e!r}, fallback to None\")\n",
      "/home/mix/Documents/SagasuSubs/SagasuSubs/patch.py:59: UserWarning: Failed to parse field f='end',v='0:00:-10.-60' due to AttributeError(\"'NoneType' object has no attribute 'groups'\"), fallback to None\n",
      "  warn(f\"Failed to parse field {f=!r},{v=!r} due to {e!r}, fallback to None\")\n",
      "/home/mix/Documents/SagasuSubs/SagasuSubs/patch.py:59: UserWarning: Failed to parse field f='start',v='0:00:-6.-45' due to AttributeError(\"'NoneType' object has no attribute 'groups'\"), fallback to None\n",
      "  warn(f\"Failed to parse field {f=!r},{v=!r} due to {e!r}, fallback to None\")\n",
      "/home/mix/Documents/SagasuSubs/SagasuSubs/patch.py:59: UserWarning: Failed to parse field f='end',v='0:00:-5.-18' due to AttributeError(\"'NoneType' object has no attribute 'groups'\"), fallback to None\n",
      "  warn(f\"Failed to parse field {f=!r},{v=!r} due to {e!r}, fallback to None\")\n",
      "/home/mix/Documents/SagasuSubs/SagasuSubs/patch.py:59: UserWarning: Failed to parse field f='start',v='0:00:-5.-6' due to AttributeError(\"'NoneType' object has no attribute 'groups'\"), fallback to None\n",
      "  warn(f\"Failed to parse field {f=!r},{v=!r} due to {e!r}, fallback to None\")\n",
      "/home/mix/Documents/SagasuSubs/SagasuSubs/patch.py:59: UserWarning: Failed to parse field f='end',v='0:00:-3.-89' due to AttributeError(\"'NoneType' object has no attribute 'groups'\"), fallback to None\n",
      "  warn(f\"Failed to parse field {f=!r},{v=!r} due to {e!r}, fallback to None\")\n",
      "/home/mix/Documents/SagasuSubs/SagasuSubs/patch.py:59: UserWarning: Failed to parse field f='start',v='0:00:-3.-76' due to AttributeError(\"'NoneType' object has no attribute 'groups'\"), fallback to None\n",
      "  warn(f\"Failed to parse field {f=!r},{v=!r} due to {e!r}, fallback to None\")\n",
      "/home/mix/Documents/SagasuSubs/SagasuSubs/patch.py:59: UserWarning: Failed to parse field f='end',v='0:00:-2.-62' due to AttributeError(\"'NoneType' object has no attribute 'groups'\"), fallback to None\n",
      "  warn(f\"Failed to parse field {f=!r},{v=!r} due to {e!r}, fallback to None\")\n",
      "/home/mix/Documents/SagasuSubs/SagasuSubs/patch.py:59: UserWarning: Failed to parse field f='start',v='0:00:-2.-19' due to AttributeError(\"'NoneType' object has no attribute 'groups'\"), fallback to None\n",
      "  warn(f\"Failed to parse field {f=!r},{v=!r} due to {e!r}, fallback to None\")\n",
      "/home/mix/Documents/SagasuSubs/SagasuSubs/patch.py:59: UserWarning: Failed to parse field f='end',v='0:00:00.-5' due to AttributeError(\"'NoneType' object has no attribute 'groups'\"), fallback to None\n",
      "  warn(f\"Failed to parse field {f=!r},{v=!r} due to {e!r}, fallback to None\")\n"
     ]
    },
    {
     "name": "stdout",
     "output_type": "stream",
     "text": [
      "Error occurred during processing file subtitles/subs_list/animation/2008/(2008.4.6)绝对可怜CHILDREN/BD/[アニメ BD]/[アニメ BD] 絶対可憐チルドレン 第45話 「天賦自然！ギフト·オブ チルドレン」.ass:\n",
      "-->\tTraceback (most recent call last):\n",
      "-->\t  File \"/tmp/ipykernel_34135/4174801234.py\", line 8, in <module>\n",
      "-->\t    data = models.SubtitlePersist.from_file(file,format='ass',exclude_fx=True)\n",
      "-->\t  File \"/home/mix/Documents/SagasuSubs/SagasuSubs/models.py\", line 62, in from_file\n",
      "-->\t    DialogContent(\n",
      "-->\t  File \"pydantic/main.py\", line 406, in pydantic.main.BaseModel.__init__\n",
      "-->\tpydantic.error_wrappers.ValidationError: 2 validation errors for DialogContent\n",
      "-->\tbegin\n",
      "-->\t  none is not an allowed value (type=type_error.none.not_allowed)\n",
      "-->\tend\n",
      "-->\t  none is not an allowed value (type=type_error.none.not_allowed)\n"
     ]
    },
    {
     "name": "stderr",
     "output_type": "stream",
     "text": [
      "/home/mix/Documents/SagasuSubs/SagasuSubs/patch.py:59: UserWarning: Failed to parse field f='start',v='0:00:00.-5' due to AttributeError(\"'NoneType' object has no attribute 'groups'\"), fallback to None\n",
      "  warn(f\"Failed to parse field {f=!r},{v=!r} due to {e!r}, fallback to None\")\n",
      "/home/mix/Documents/SagasuSubs/SagasuSubs/patch.py:153: UserWarning: Failed to parse color '&H0F0F0F&' due to ValueError(\"invalid literal for int() with base 16: '0F0F0F&'\"), fallback to #000000.\n",
      "  warn(f\"Failed to parse color {rgba!r} due to {e!r}, fallback to #000000.\")\n",
      "/home/mix/Documents/SagasuSubs/SagasuSubs/patch.py:153: UserWarning: Failed to parse color '&H0#999999' due to ValueError(\"invalid literal for int() with base 16: '0#999999'\"), fallback to #000000.\n",
      "  warn(f\"Failed to parse color {rgba!r} due to {e!r}, fallback to #000000.\")\n",
      "/home/mix/Documents/SagasuSubs/SagasuSubs/patch.py:153: UserWarning: Failed to parse color '&H000000&' due to ValueError(\"invalid literal for int() with base 16: '000000&'\"), fallback to #000000.\n",
      "  warn(f\"Failed to parse color {rgba!r} due to {e!r}, fallback to #000000.\")\n",
      "/home/mix/Documents/SagasuSubs/SagasuSubs/patch.py:59: UserWarning: Failed to parse field f='end',v='0:00:00.-10' due to AttributeError(\"'NoneType' object has no attribute 'groups'\"), fallback to None\n",
      "  warn(f\"Failed to parse field {f=!r},{v=!r} due to {e!r}, fallback to None\")\n"
     ]
    },
    {
     "name": "stdout",
     "output_type": "stream",
     "text": [
      "Error occurred during processing file subtitles/subs_list/animation/2010/(2010.10.8)魔法禁书目录 S2/BD/[YYDM-11FANS]/[YYDM-11FANS][Toaru_Majutsu_no_Index_II][12][BDRIP][X264_AAC][1280X720].sc.ass:\n",
      "-->\tTraceback (most recent call last):\n",
      "-->\t  File \"/tmp/ipykernel_34135/4174801234.py\", line 8, in <module>\n",
      "-->\t    data = models.SubtitlePersist.from_file(file,format='ass',exclude_fx=True)\n",
      "-->\t  File \"/home/mix/Documents/SagasuSubs/SagasuSubs/models.py\", line 62, in from_file\n",
      "-->\t    DialogContent(\n",
      "-->\t  File \"pydantic/main.py\", line 406, in pydantic.main.BaseModel.__init__\n",
      "-->\tpydantic.error_wrappers.ValidationError: 1 validation error for DialogContent\n",
      "-->\tend\n",
      "-->\t  none is not an allowed value (type=type_error.none.not_allowed)\n",
      "Error occurred during processing file subtitles/subs_list/animation/2010/(2010.10.8)魔法禁书目录 S2/BD/[YYDM-11FANS]/[YYDM-11FANS][Toaru_Majutsu_no_Index_II][12][BDRIP][X264_AAC][1280X720].tc.ass:\n",
      "-->\tTraceback (most recent call last):\n",
      "-->\t  File \"/tmp/ipykernel_34135/4174801234.py\", line 8, in <module>\n",
      "-->\t    data = models.SubtitlePersist.from_file(file,format='ass',exclude_fx=True)\n",
      "-->\t  File \"/home/mix/Documents/SagasuSubs/SagasuSubs/models.py\", line 62, in from_file\n",
      "-->\t    DialogContent(\n",
      "-->\t  File \"pydantic/main.py\", line 406, in pydantic.main.BaseModel.__init__\n",
      "-->\tpydantic.error_wrappers.ValidationError: 1 validation error for DialogContent\n",
      "-->\tend\n",
      "-->\t  none is not an allowed value (type=type_error.none.not_allowed)\n"
     ]
    },
    {
     "name": "stderr",
     "output_type": "stream",
     "text": [
      "/home/mix/Documents/SagasuSubs/SagasuSubs/patch.py:153: UserWarning: Failed to parse color '&H3C99CF&' due to ValueError(\"invalid literal for int() with base 16: '3C99CF&'\"), fallback to #000000.\n",
      "  warn(f\"Failed to parse color {rgba!r} due to {e!r}, fallback to #000000.\")\n",
      "/home/mix/Documents/SagasuSubs/SagasuSubs/patch.py:153: UserWarning: Failed to parse color '&H4D603D&' due to ValueError(\"invalid literal for int() with base 16: '4D603D&'\"), fallback to #000000.\n",
      "  warn(f\"Failed to parse color {rgba!r} due to {e!r}, fallback to #000000.\")\n",
      "/home/mix/Documents/SagasuSubs/SagasuSubs/patch.py:59: UserWarning: Failed to parse field f='end',v='0' due to AttributeError(\"'NoneType' object has no attribute 'groups'\"), fallback to None\n",
      "  warn(f\"Failed to parse field {f=!r},{v=!r} due to {e!r}, fallback to None\")\n",
      "/home/mix/Documents/SagasuSubs/SagasuSubs/patch.py:59: UserWarning: Failed to parse field f='marginl',v='' due to ValueError(\"invalid literal for int() with base 10: ''\"), fallback to None\n",
      "  warn(f\"Failed to parse field {f=!r},{v=!r} due to {e!r}, fallback to None\")\n"
     ]
    },
    {
     "name": "stdout",
     "output_type": "stream",
     "text": [
      "Error occurred during processing file subtitles/subs_list/animation/2011/(2011.10.4)魔剑姬/BD/DHR/Maken-ki! - 10 (BD 1280x720 AVC AAC).ass:\n",
      "-->\tTraceback (most recent call last):\n",
      "-->\t  File \"/tmp/ipykernel_34135/4174801234.py\", line 8, in <module>\n",
      "-->\t    data = models.SubtitlePersist.from_file(file,format='ass',exclude_fx=True)\n",
      "-->\t  File \"/home/mix/Documents/SagasuSubs/SagasuSubs/models.py\", line 62, in from_file\n",
      "-->\t    DialogContent(\n",
      "-->\t  File \"pydantic/main.py\", line 406, in pydantic.main.BaseModel.__init__\n",
      "-->\tpydantic.error_wrappers.ValidationError: 1 validation error for DialogContent\n",
      "-->\tend\n",
      "-->\t  none is not an allowed value (type=type_error.none.not_allowed)\n"
     ]
    },
    {
     "name": "stderr",
     "output_type": "stream",
     "text": [
      "/home/mix/Documents/SagasuSubs/SagasuSubs/patch.py:59: UserWarning: Failed to parse field f='start',v='0:00:-10.00' due to AttributeError(\"'NoneType' object has no attribute 'groups'\"), fallback to None\n",
      "  warn(f\"Failed to parse field {f=!r},{v=!r} due to {e!r}, fallback to None\")\n",
      "/home/mix/Documents/SagasuSubs/SagasuSubs/patch.py:59: UserWarning: Failed to parse field f='end',v='0:00:-10.00' due to AttributeError(\"'NoneType' object has no attribute 'groups'\"), fallback to None\n",
      "  warn(f\"Failed to parse field {f=!r},{v=!r} due to {e!r}, fallback to None\")\n"
     ]
    },
    {
     "name": "stdout",
     "output_type": "stream",
     "text": [
      "Error occurred during processing file subtitles/subs_list/animation/2011/(2011.7.7)回转企鹅罐/BD/[110707][BDRIP]輪るピングドラム/23RD STATION 運命の至る場所.GB.ass:\n",
      "-->\tTraceback (most recent call last):\n",
      "-->\t  File \"/tmp/ipykernel_34135/4174801234.py\", line 8, in <module>\n",
      "-->\t    data = models.SubtitlePersist.from_file(file,format='ass',exclude_fx=True)\n",
      "-->\t  File \"/home/mix/Documents/SagasuSubs/SagasuSubs/models.py\", line 62, in from_file\n",
      "-->\t    DialogContent(\n",
      "-->\t  File \"pydantic/main.py\", line 406, in pydantic.main.BaseModel.__init__\n",
      "-->\tpydantic.error_wrappers.ValidationError: 2 validation errors for DialogContent\n",
      "-->\tbegin\n",
      "-->\t  none is not an allowed value (type=type_error.none.not_allowed)\n",
      "-->\tend\n",
      "-->\t  none is not an allowed value (type=type_error.none.not_allowed)\n",
      "Error occurred during processing file subtitles/subs_list/animation/2011/(2011.7.7)回转企鹅罐/BD/[110707][BDRIP]輪るピングドラム/19TH STATION 私の運命の人.GB.ass:\n",
      "-->\tTraceback (most recent call last):\n",
      "-->\t  File \"/tmp/ipykernel_34135/4174801234.py\", line 8, in <module>\n",
      "-->\t    data = models.SubtitlePersist.from_file(file,format='ass',exclude_fx=True)\n",
      "-->\t  File \"/home/mix/Documents/SagasuSubs/SagasuSubs/models.py\", line 62, in from_file\n",
      "-->\t    DialogContent(\n",
      "-->\t  File \"pydantic/main.py\", line 406, in pydantic.main.BaseModel.__init__\n",
      "-->\tpydantic.error_wrappers.ValidationError: 2 validation errors for DialogContent\n",
      "-->\tbegin\n",
      "-->\t  none is not an allowed value (type=type_error.none.not_allowed)\n",
      "-->\tend\n",
      "-->\t  none is not an allowed value (type=type_error.none.not_allowed)\n"
     ]
    },
    {
     "name": "stderr",
     "output_type": "stream",
     "text": [
      "/home/mix/Documents/SagasuSubs/SagasuSubs/patch.py:59: UserWarning: Failed to parse field f='start',v='0:00:-9.-90' due to AttributeError(\"'NoneType' object has no attribute 'groups'\"), fallback to None\n",
      "  warn(f\"Failed to parse field {f=!r},{v=!r} due to {e!r}, fallback to None\")\n",
      "/home/mix/Documents/SagasuSubs/SagasuSubs/patch.py:59: UserWarning: Failed to parse field f='end',v='0:00:-9.-90' due to AttributeError(\"'NoneType' object has no attribute 'groups'\"), fallback to None\n",
      "  warn(f\"Failed to parse field {f=!r},{v=!r} due to {e!r}, fallback to None\")\n",
      "/home/mix/Documents/SagasuSubs/SagasuSubs/patch.py:59: UserWarning: Failed to parse field f='start',v='0:00:-9.-75' due to AttributeError(\"'NoneType' object has no attribute 'groups'\"), fallback to None\n",
      "  warn(f\"Failed to parse field {f=!r},{v=!r} due to {e!r}, fallback to None\")\n",
      "/home/mix/Documents/SagasuSubs/SagasuSubs/patch.py:59: UserWarning: Failed to parse field f='end',v='0:00:-9.-75' due to AttributeError(\"'NoneType' object has no attribute 'groups'\"), fallback to None\n",
      "  warn(f\"Failed to parse field {f=!r},{v=!r} due to {e!r}, fallback to None\")\n",
      "/home/mix/Documents/SagasuSubs/SagasuSubs/patch.py:59: UserWarning: Failed to parse field f='start',v='0:00:00.-86' due to AttributeError(\"'NoneType' object has no attribute 'groups'\"), fallback to None\n",
      "  warn(f\"Failed to parse field {f=!r},{v=!r} due to {e!r}, fallback to None\")\n",
      "/home/mix/Documents/SagasuSubs/SagasuSubs/patch.py:59: UserWarning: Failed to parse field f='end',v='0:00:00.-86' due to AttributeError(\"'NoneType' object has no attribute 'groups'\"), fallback to None\n",
      "  warn(f\"Failed to parse field {f=!r},{v=!r} due to {e!r}, fallback to None\")\n",
      "/home/mix/Documents/SagasuSubs/SagasuSubs/patch.py:59: UserWarning: Failed to parse field f='start',v='0:00:00.-94' due to AttributeError(\"'NoneType' object has no attribute 'groups'\"), fallback to None\n",
      "  warn(f\"Failed to parse field {f=!r},{v=!r} due to {e!r}, fallback to None\")\n",
      "/home/mix/Documents/SagasuSubs/SagasuSubs/patch.py:59: UserWarning: Failed to parse field f='end',v='0:00:00.-94' due to AttributeError(\"'NoneType' object has no attribute 'groups'\"), fallback to None\n",
      "  warn(f\"Failed to parse field {f=!r},{v=!r} due to {e!r}, fallback to None\")\n",
      "/home/mix/Documents/SagasuSubs/SagasuSubs/patch.py:59: UserWarning: Failed to parse field f='start',v='0:0:08.00' due to AttributeError(\"'NoneType' object has no attribute 'groups'\"), fallback to None\n",
      "  warn(f\"Failed to parse field {f=!r},{v=!r} due to {e!r}, fallback to None\")\n"
     ]
    },
    {
     "name": "stdout",
     "output_type": "stream",
     "text": [
      "Error occurred during processing file subtitles/subs_list/animation/2012/(2012.10.8)樱花庄的宠物女孩/BD/樱律/BD（部分校对）/中日双语版/樱花庄的宠物女孩01.ass:\n",
      "-->\tTraceback (most recent call last):\n",
      "-->\t  File \"/tmp/ipykernel_34135/4174801234.py\", line 8, in <module>\n",
      "-->\t    data = models.SubtitlePersist.from_file(file,format='ass',exclude_fx=True)\n",
      "-->\t  File \"/home/mix/Documents/SagasuSubs/SagasuSubs/models.py\", line 62, in from_file\n",
      "-->\t    DialogContent(\n",
      "-->\t  File \"pydantic/main.py\", line 406, in pydantic.main.BaseModel.__init__\n",
      "-->\tpydantic.error_wrappers.ValidationError: 1 validation error for DialogContent\n",
      "-->\tbegin\n",
      "-->\t  none is not an allowed value (type=type_error.none.not_allowed)\n",
      "Error occurred during processing file subtitles/subs_list/animation/2012/(2012.10.8)樱花庄的宠物女孩/TV/樱律/中日双语版/樱花庄的宠物女孩01.ass:\n",
      "-->\tTraceback (most recent call last):\n",
      "-->\t  File \"/tmp/ipykernel_34135/4174801234.py\", line 8, in <module>\n",
      "-->\t    data = models.SubtitlePersist.from_file(file,format='ass',exclude_fx=True)\n",
      "-->\t  File \"/home/mix/Documents/SagasuSubs/SagasuSubs/models.py\", line 62, in from_file\n",
      "-->\t    DialogContent(\n",
      "-->\t  File \"pydantic/main.py\", line 406, in pydantic.main.BaseModel.__init__\n",
      "-->\tpydantic.error_wrappers.ValidationError: 1 validation error for DialogContent\n",
      "-->\tbegin\n",
      "-->\t  none is not an allowed value (type=type_error.none.not_allowed)\n"
     ]
    },
    {
     "name": "stderr",
     "output_type": "stream",
     "text": [
      "/home/mix/Documents/SagasuSubs/SagasuSubs/patch.py:153: UserWarning: Failed to parse color '&HC69392&' due to ValueError(\"invalid literal for int() with base 16: 'C69392&'\"), fallback to #000000.\n",
      "  warn(f\"Failed to parse color {rgba!r} due to {e!r}, fallback to #000000.\")\n",
      "/home/mix/Documents/SagasuSubs/SagasuSubs/patch.py:59: UserWarning: Failed to parse field f='fontsize',v='&H00FFFFFF' due to ValueError(\"could not convert string to float: '&H00FFFFFF'\"), fallback to None\n",
      "  warn(f\"Failed to parse field {f=!r},{v=!r} due to {e!r}, fallback to None\")\n",
      "/home/mix/Documents/SagasuSubs/SagasuSubs/patch.py:59: UserWarning: Failed to parse field f='encoding',v='1Style: SCREEN' due to ValueError(\"invalid literal for int() with base 10: '1Style: SCREEN'\"), fallback to None\n",
      "  warn(f\"Failed to parse field {f=!r},{v=!r} due to {e!r}, fallback to None\")\n",
      "/home/mix/Documents/SagasuSubs/SagasuSubs/patch.py:59: UserWarning: Failed to parse field f='end',v='0:00:12.5話3' due to AttributeError(\"'NoneType' object has no attribute 'groups'\"), fallback to None\n",
      "  warn(f\"Failed to parse field {f=!r},{v=!r} due to {e!r}, fallback to None\")\n",
      "/home/mix/Documents/SagasuSubs/SagasuSubs/patch.py:59: UserWarning: Failed to parse field f='start',v='0:00:12.5話3' due to AttributeError(\"'NoneType' object has no attribute 'groups'\"), fallback to None\n",
      "  warn(f\"Failed to parse field {f=!r},{v=!r} due to {e!r}, fallback to None\")\n",
      "/home/mix/Documents/SagasuSubs/SagasuSubs/patch.py:59: UserWarning: Failed to parse field f='end',v='0:00:12.5話7' due to AttributeError(\"'NoneType' object has no attribute 'groups'\"), fallback to None\n",
      "  warn(f\"Failed to parse field {f=!r},{v=!r} due to {e!r}, fallback to None\")\n",
      "/home/mix/Documents/SagasuSubs/SagasuSubs/patch.py:59: UserWarning: Failed to parse field f='start',v='0:00:12.5話7' due to AttributeError(\"'NoneType' object has no attribute 'groups'\"), fallback to None\n",
      "  warn(f\"Failed to parse field {f=!r},{v=!r} due to {e!r}, fallback to None\")\n",
      "/home/mix/Documents/SagasuSubs/SagasuSubs/patch.py:59: UserWarning: Failed to parse field f='end',v='0:01:02.5話0' due to AttributeError(\"'NoneType' object has no attribute 'groups'\"), fallback to None\n",
      "  warn(f\"Failed to parse field {f=!r},{v=!r} due to {e!r}, fallback to None\")\n",
      "/home/mix/Documents/SagasuSubs/SagasuSubs/patch.py:59: UserWarning: Failed to parse field f='start',v='0:01:02.5話0' due to AttributeError(\"'NoneType' object has no attribute 'groups'\"), fallback to None\n",
      "  warn(f\"Failed to parse field {f=!r},{v=!r} due to {e!r}, fallback to None\")\n"
     ]
    },
    {
     "name": "stdout",
     "output_type": "stream",
     "text": [
      "Error occurred during processing file subtitles/subs_list/animation/2013/(2013.4.5)百花缭乱 武士新娘/BD/Hyakka Ryouran _Samurai Bride_ - SP/Hyakka Ryouran ~Samurai Bride~ - SP1 [BDRip 1920x1080 x264 FLAC].ass:\n",
      "-->\tTraceback (most recent call last):\n",
      "-->\t  File \"/tmp/ipykernel_34135/4174801234.py\", line 8, in <module>\n",
      "-->\t    data = models.SubtitlePersist.from_file(file,format='ass',exclude_fx=True)\n",
      "-->\t  File \"/home/mix/Documents/SagasuSubs/SagasuSubs/models.py\", line 62, in from_file\n",
      "-->\t    DialogContent(\n",
      "-->\t  File \"pydantic/main.py\", line 406, in pydantic.main.BaseModel.__init__\n",
      "-->\tpydantic.error_wrappers.ValidationError: 1 validation error for DialogContent\n",
      "-->\tend\n",
      "-->\t  none is not an allowed value (type=type_error.none.not_allowed)\n",
      "Error occurred during processing file subtitles/subs_list/animation/2013/(2013.4.5)百花缭乱 武士新娘/BD/Seed-Raws百花缭乱(含OVA+SP)[简]/Hyakka Ryouran Samurai Bride - Vol.01 SP (BD 1280x720 AVC AAC).ass:\n",
      "-->\tTraceback (most recent call last):\n",
      "-->\t  File \"/tmp/ipykernel_34135/4174801234.py\", line 8, in <module>\n",
      "-->\t    data = models.SubtitlePersist.from_file(file,format='ass',exclude_fx=True)\n",
      "-->\t  File \"/home/mix/Documents/SagasuSubs/SagasuSubs/models.py\", line 62, in from_file\n",
      "-->\t    DialogContent(\n",
      "-->\t  File \"pydantic/main.py\", line 406, in pydantic.main.BaseModel.__init__\n",
      "-->\tpydantic.error_wrappers.ValidationError: 1 validation error for DialogContent\n",
      "-->\tend\n",
      "-->\t  none is not an allowed value (type=type_error.none.not_allowed)\n"
     ]
    },
    {
     "name": "stderr",
     "output_type": "stream",
     "text": [
      "/home/mix/Documents/SagasuSubs/SagasuSubs/patch.py:153: UserWarning: Failed to parse color ' &H00FFFFFF' due to ValueError(\"invalid literal for int() with base 10: ' &H00FFFFFF'\"), fallback to #000000.\n",
      "  warn(f\"Failed to parse color {rgba!r} due to {e!r}, fallback to #000000.\")\n",
      "/home/mix/Documents/SagasuSubs/SagasuSubs/patch.py:153: UserWarning: Failed to parse color ' &H000000FF' due to ValueError(\"invalid literal for int() with base 10: ' &H000000FF'\"), fallback to #000000.\n",
      "  warn(f\"Failed to parse color {rgba!r} due to {e!r}, fallback to #000000.\")\n",
      "/home/mix/Documents/SagasuSubs/SagasuSubs/patch.py:153: UserWarning: Failed to parse color ' &H00000000' due to ValueError(\"invalid literal for int() with base 10: ' &H00000000'\"), fallback to #000000.\n",
      "  warn(f\"Failed to parse color {rgba!r} due to {e!r}, fallback to #000000.\")\n",
      "/home/mix/Documents/SagasuSubs/SagasuSubs/patch.py:153: UserWarning: Failed to parse color ' &H00E8F0E9' due to ValueError(\"invalid literal for int() with base 10: ' &H00E8F0E9'\"), fallback to #000000.\n",
      "  warn(f\"Failed to parse color {rgba!r} due to {e!r}, fallback to #000000.\")\n",
      "/home/mix/Documents/SagasuSubs/SagasuSubs/patch.py:59: UserWarning: Failed to parse field f='layer',v='Marked=0' due to ValueError(\"invalid literal for int() with base 10: 'Marked=0'\"), fallback to None\n",
      "  warn(f\"Failed to parse field {f=!r},{v=!r} due to {e!r}, fallback to None\")\n",
      "/home/mix/Documents/SagasuSubs/SagasuSubs/patch.py:59: UserWarning: Failed to parse field f='start',v='0:00:-9.00' due to AttributeError(\"'NoneType' object has no attribute 'groups'\"), fallback to None\n",
      "  warn(f\"Failed to parse field {f=!r},{v=!r} due to {e!r}, fallback to None\")\n",
      "/home/mix/Documents/SagasuSubs/SagasuSubs/patch.py:59: UserWarning: Failed to parse field f='end',v='0:00:-9.00' due to AttributeError(\"'NoneType' object has no attribute 'groups'\"), fallback to None\n",
      "  warn(f\"Failed to parse field {f=!r},{v=!r} due to {e!r}, fallback to None\")\n",
      "/home/mix/Documents/SagasuSubs/SagasuSubs/patch.py:59: UserWarning: Failed to parse field f='start',v='0:00:-8.00' due to AttributeError(\"'NoneType' object has no attribute 'groups'\"), fallback to None\n",
      "  warn(f\"Failed to parse field {f=!r},{v=!r} due to {e!r}, fallback to None\")\n",
      "/home/mix/Documents/SagasuSubs/SagasuSubs/patch.py:59: UserWarning: Failed to parse field f='end',v='0:00:-8.00' due to AttributeError(\"'NoneType' object has no attribute 'groups'\"), fallback to None\n",
      "  warn(f\"Failed to parse field {f=!r},{v=!r} due to {e!r}, fallback to None\")\n",
      "/home/mix/Documents/SagasuSubs/SagasuSubs/patch.py:59: UserWarning: Failed to parse field f='start',v='0:00:-1.-85' due to AttributeError(\"'NoneType' object has no attribute 'groups'\"), fallback to None\n",
      "  warn(f\"Failed to parse field {f=!r},{v=!r} due to {e!r}, fallback to None\")\n",
      "/home/mix/Documents/SagasuSubs/SagasuSubs/patch.py:59: UserWarning: Failed to parse field f='end',v='0:00:00.-22' due to AttributeError(\"'NoneType' object has no attribute 'groups'\"), fallback to None\n",
      "  warn(f\"Failed to parse field {f=!r},{v=!r} due to {e!r}, fallback to None\")\n"
     ]
    },
    {
     "name": "stdout",
     "output_type": "stream",
     "text": [
      "Error occurred during processing file subtitles/subs_list/animation/2015/(2015.1.23)ISUCA 依丝卡/BD/[依丝卡][ISUCA][イスカ][BDrip][1920x1080][TV 01-10][H264 FLAC MKV][EMD 简体字幕][对应BD字幕][无OVA 字幕]/[ISUCA][09][BDRIP][1080P][H264_FLAC].ass:\n",
      "-->\tTraceback (most recent call last):\n",
      "-->\t  File \"/tmp/ipykernel_34135/4174801234.py\", line 8, in <module>\n",
      "-->\t    data = models.SubtitlePersist.from_file(file,format='ass',exclude_fx=True)\n",
      "-->\t  File \"/home/mix/Documents/SagasuSubs/SagasuSubs/models.py\", line 62, in from_file\n",
      "-->\t    DialogContent(\n",
      "-->\t  File \"pydantic/main.py\", line 406, in pydantic.main.BaseModel.__init__\n",
      "-->\tpydantic.error_wrappers.ValidationError: 2 validation errors for DialogContent\n",
      "-->\tbegin\n",
      "-->\t  none is not an allowed value (type=type_error.none.not_allowed)\n",
      "-->\tend\n",
      "-->\t  none is not an allowed value (type=type_error.none.not_allowed)\n",
      "Error occurred during processing file subtitles/subs_list/animation/2015/(2015.1.8)铳皇无尽的法夫纳/BD/[VCB-Studio] 枪皇无尽的法夫纳BDRip 简体字幕/[VCB-S&philosophy-raws][Unlimited Fafnir][BDRIP][09][Hi10P FLAC][1920X1080].sc.ass:\n",
      "-->\tTraceback (most recent call last):\n",
      "-->\t  File \"/tmp/ipykernel_34135/4174801234.py\", line 8, in <module>\n",
      "-->\t    data = models.SubtitlePersist.from_file(file,format='ass',exclude_fx=True)\n",
      "-->\t  File \"/home/mix/Documents/SagasuSubs/SagasuSubs/models.py\", line 62, in from_file\n",
      "-->\t    DialogContent(\n",
      "-->\t  File \"pydantic/main.py\", line 406, in pydantic.main.BaseModel.__init__\n",
      "-->\tpydantic.error_wrappers.ValidationError: 2 validation errors for DialogContent\n",
      "-->\tbegin\n",
      "-->\t  none is not an allowed value (type=type_error.none.not_allowed)\n",
      "-->\tend\n",
      "-->\t  none is not an allowed value (type=type_error.none.not_allowed)\n",
      "Error occurred during processing file subtitles/subs_list/animation/2015/(2015.1.8)铳皇无尽的法夫纳/BD/[VCB-Studio] 枪皇无尽的法夫纳BDRip 简体字幕/[VCB-S&philosophy-raws][Unlimited Fafnir][BDRIP][10][Hi10P FLAC][1920X1080].sc.ass:\n",
      "-->\tTraceback (most recent call last):\n",
      "-->\t  File \"/tmp/ipykernel_34135/4174801234.py\", line 8, in <module>\n",
      "-->\t    data = models.SubtitlePersist.from_file(file,format='ass',exclude_fx=True)\n",
      "-->\t  File \"/home/mix/Documents/SagasuSubs/SagasuSubs/models.py\", line 62, in from_file\n",
      "-->\t    DialogContent(\n",
      "-->\t  File \"pydantic/main.py\", line 406, in pydantic.main.BaseModel.__init__\n",
      "-->\tpydantic.error_wrappers.ValidationError: 2 validation errors for DialogContent\n",
      "-->\tbegin\n",
      "-->\t  none is not an allowed value (type=type_error.none.not_allowed)\n",
      "-->\tend\n",
      "-->\t  none is not an allowed value (type=type_error.none.not_allowed)\n",
      "Error occurred during processing file subtitles/subs_list/animation/2015/(2015.1.8)铳皇无尽的法夫纳/BD/[VCB-Studio] 枪皇无尽的法夫纳BDRip 简体字幕/[VCB-S&philosophy-raws][Unlimited Fafnir][BDRIP][11][Hi10P FLAC][1920X1080].sc.ass:\n",
      "-->\tTraceback (most recent call last):\n",
      "-->\t  File \"/tmp/ipykernel_34135/4174801234.py\", line 8, in <module>\n",
      "-->\t    data = models.SubtitlePersist.from_file(file,format='ass',exclude_fx=True)\n",
      "-->\t  File \"/home/mix/Documents/SagasuSubs/SagasuSubs/models.py\", line 62, in from_file\n",
      "-->\t    DialogContent(\n",
      "-->\t  File \"pydantic/main.py\", line 406, in pydantic.main.BaseModel.__init__\n",
      "-->\tpydantic.error_wrappers.ValidationError: 2 validation errors for DialogContent\n",
      "-->\tbegin\n",
      "-->\t  none is not an allowed value (type=type_error.none.not_allowed)\n",
      "-->\tend\n",
      "-->\t  none is not an allowed value (type=type_error.none.not_allowed)\n"
     ]
    },
    {
     "name": "stderr",
     "output_type": "stream",
     "text": [
      "/home/mix/Documents/SagasuSubs/SagasuSubs/patch.py:59: UserWarning: Failed to parse field f='start',v='0:00:-8.-98' due to AttributeError(\"'NoneType' object has no attribute 'groups'\"), fallback to None\n",
      "  warn(f\"Failed to parse field {f=!r},{v=!r} due to {e!r}, fallback to None\")\n",
      "/home/mix/Documents/SagasuSubs/SagasuSubs/patch.py:59: UserWarning: Failed to parse field f='end',v='0:00:-8.-98' due to AttributeError(\"'NoneType' object has no attribute 'groups'\"), fallback to None\n",
      "  warn(f\"Failed to parse field {f=!r},{v=!r} due to {e!r}, fallback to None\")\n"
     ]
    },
    {
     "name": "stdout",
     "output_type": "stream",
     "text": [
      "Error occurred during processing file subtitles/subs_list/animation/2015/(2015.1.8)铳皇无尽的法夫纳/BD/枪皇无尽的法夫纳BDRip/[reinforce] juuou mujin no fafnir - 09 (bdrip 1920x1080 x264 flac).ass:\n",
      "-->\tTraceback (most recent call last):\n",
      "-->\t  File \"/tmp/ipykernel_34135/4174801234.py\", line 8, in <module>\n",
      "-->\t    data = models.SubtitlePersist.from_file(file,format='ass',exclude_fx=True)\n",
      "-->\t  File \"/home/mix/Documents/SagasuSubs/SagasuSubs/models.py\", line 62, in from_file\n",
      "-->\t    DialogContent(\n",
      "-->\t  File \"pydantic/main.py\", line 406, in pydantic.main.BaseModel.__init__\n",
      "-->\tpydantic.error_wrappers.ValidationError: 2 validation errors for DialogContent\n",
      "-->\tbegin\n",
      "-->\t  none is not an allowed value (type=type_error.none.not_allowed)\n",
      "-->\tend\n",
      "-->\t  none is not an allowed value (type=type_error.none.not_allowed)\n",
      "Error occurred during processing file subtitles/subs_list/animation/2015/(2015.1.8)铳皇无尽的法夫纳/BD/枪皇无尽的法夫纳BDRip/[reinforce] juuou mujin no fafnir - 10 (bdrip 1920x1080 x264 flac).ass:\n",
      "-->\tTraceback (most recent call last):\n",
      "-->\t  File \"/tmp/ipykernel_34135/4174801234.py\", line 8, in <module>\n",
      "-->\t    data = models.SubtitlePersist.from_file(file,format='ass',exclude_fx=True)\n",
      "-->\t  File \"/home/mix/Documents/SagasuSubs/SagasuSubs/models.py\", line 62, in from_file\n",
      "-->\t    DialogContent(\n",
      "-->\t  File \"pydantic/main.py\", line 406, in pydantic.main.BaseModel.__init__\n",
      "-->\tpydantic.error_wrappers.ValidationError: 2 validation errors for DialogContent\n",
      "-->\tbegin\n",
      "-->\t  none is not an allowed value (type=type_error.none.not_allowed)\n",
      "-->\tend\n",
      "-->\t  none is not an allowed value (type=type_error.none.not_allowed)\n",
      "Error occurred during processing file subtitles/subs_list/animation/2015/(2015.1.8)铳皇无尽的法夫纳/BD/枪皇无尽的法夫纳BDRip/[reinforce] juuou mujin no fafnir - 11 (bdrip 1920x1080 x264 flac).ass:\n",
      "-->\tTraceback (most recent call last):\n",
      "-->\t  File \"/tmp/ipykernel_34135/4174801234.py\", line 8, in <module>\n",
      "-->\t    data = models.SubtitlePersist.from_file(file,format='ass',exclude_fx=True)\n",
      "-->\t  File \"/home/mix/Documents/SagasuSubs/SagasuSubs/models.py\", line 62, in from_file\n",
      "-->\t    DialogContent(\n",
      "-->\t  File \"pydantic/main.py\", line 406, in pydantic.main.BaseModel.__init__\n",
      "-->\tpydantic.error_wrappers.ValidationError: 2 validation errors for DialogContent\n",
      "-->\tbegin\n",
      "-->\t  none is not an allowed value (type=type_error.none.not_allowed)\n",
      "-->\tend\n",
      "-->\t  none is not an allowed value (type=type_error.none.not_allowed)\n",
      "Error occurred during processing file subtitles/subs_list/animation/2015/(2015.1.8)铳皇无尽的法夫纳/BD/简体OPED歌词字幕修正/[VCB-Studio] Juuou Mujin no Fafnir [09][Ma10p_1080p][x265_2flac].sc.ass:\n",
      "-->\tTraceback (most recent call last):\n",
      "-->\t  File \"/tmp/ipykernel_34135/4174801234.py\", line 8, in <module>\n",
      "-->\t    data = models.SubtitlePersist.from_file(file,format='ass',exclude_fx=True)\n",
      "-->\t  File \"/home/mix/Documents/SagasuSubs/SagasuSubs/models.py\", line 62, in from_file\n",
      "-->\t    DialogContent(\n",
      "-->\t  File \"pydantic/main.py\", line 406, in pydantic.main.BaseModel.__init__\n",
      "-->\tpydantic.error_wrappers.ValidationError: 2 validation errors for DialogContent\n",
      "-->\tbegin\n",
      "-->\t  none is not an allowed value (type=type_error.none.not_allowed)\n",
      "-->\tend\n",
      "-->\t  none is not an allowed value (type=type_error.none.not_allowed)\n",
      "Error occurred during processing file subtitles/subs_list/animation/2015/(2015.1.8)铳皇无尽的法夫纳/BD/简体OPED歌词字幕修正/[VCB-Studio] Juuou Mujin no Fafnir [10][Ma10p_1080p][x265_2flac].sc.ass:\n",
      "-->\tTraceback (most recent call last):\n",
      "-->\t  File \"/tmp/ipykernel_34135/4174801234.py\", line 8, in <module>\n",
      "-->\t    data = models.SubtitlePersist.from_file(file,format='ass',exclude_fx=True)\n",
      "-->\t  File \"/home/mix/Documents/SagasuSubs/SagasuSubs/models.py\", line 62, in from_file\n",
      "-->\t    DialogContent(\n",
      "-->\t  File \"pydantic/main.py\", line 406, in pydantic.main.BaseModel.__init__\n",
      "-->\tpydantic.error_wrappers.ValidationError: 2 validation errors for DialogContent\n",
      "-->\tbegin\n",
      "-->\t  none is not an allowed value (type=type_error.none.not_allowed)\n",
      "-->\tend\n",
      "-->\t  none is not an allowed value (type=type_error.none.not_allowed)\n",
      "Error occurred during processing file subtitles/subs_list/animation/2015/(2015.1.8)铳皇无尽的法夫纳/BD/简体OPED歌词字幕修正/[VCB-Studio] Juuou Mujin no Fafnir [11][Ma10p_1080p][x265_2flac].sc.ass:\n",
      "-->\tTraceback (most recent call last):\n",
      "-->\t  File \"/tmp/ipykernel_34135/4174801234.py\", line 8, in <module>\n",
      "-->\t    data = models.SubtitlePersist.from_file(file,format='ass',exclude_fx=True)\n",
      "-->\t  File \"/home/mix/Documents/SagasuSubs/SagasuSubs/models.py\", line 62, in from_file\n",
      "-->\t    DialogContent(\n",
      "-->\t  File \"pydantic/main.py\", line 406, in pydantic.main.BaseModel.__init__\n",
      "-->\tpydantic.error_wrappers.ValidationError: 2 validation errors for DialogContent\n",
      "-->\tbegin\n",
      "-->\t  none is not an allowed value (type=type_error.none.not_allowed)\n",
      "-->\tend\n",
      "-->\t  none is not an allowed value (type=type_error.none.not_allowed)\n"
     ]
    },
    {
     "name": "stderr",
     "output_type": "stream",
     "text": [
      "/home/mix/Documents/SagasuSubs/SagasuSubs/patch.py:59: UserWarning: Failed to parse field f='start',v='0:00:-01.00' due to AttributeError(\"'NoneType' object has no attribute 'groups'\"), fallback to None\n",
      "  warn(f\"Failed to parse field {f=!r},{v=!r} due to {e!r}, fallback to None\")\n",
      "/home/mix/Documents/SagasuSubs/SagasuSubs/patch.py:59: UserWarning: Failed to parse field f='end',v='0:00:00.-98' due to AttributeError(\"'NoneType' object has no attribute 'groups'\"), fallback to None\n",
      "  warn(f\"Failed to parse field {f=!r},{v=!r} due to {e!r}, fallback to None\")\n",
      "/home/mix/Documents/SagasuSubs/SagasuSubs/patch.py:59: UserWarning: Failed to parse field f='start',v='0:00:-08.-98' due to AttributeError(\"'NoneType' object has no attribute 'groups'\"), fallback to None\n",
      "  warn(f\"Failed to parse field {f=!r},{v=!r} due to {e!r}, fallback to None\")\n",
      "/home/mix/Documents/SagasuSubs/SagasuSubs/patch.py:59: UserWarning: Failed to parse field f='end',v='0:00:-06.-98' due to AttributeError(\"'NoneType' object has no attribute 'groups'\"), fallback to None\n",
      "  warn(f\"Failed to parse field {f=!r},{v=!r} due to {e!r}, fallback to None\")\n",
      "/home/mix/Documents/SagasuSubs/SagasuSubs/patch.py:59: UserWarning: Failed to parse field f='layer',v=': 0' due to ValueError(\"invalid literal for int() with base 10: ': 0'\"), fallback to None\n",
      "  warn(f\"Failed to parse field {f=!r},{v=!r} due to {e!r}, fallback to None\")\n"
     ]
    },
    {
     "name": "stdout",
     "output_type": "stream",
     "text": [
      "Error occurred during processing file subtitles/subs_list/animation/2016/(2016.10.1)ViVid Strike!(S5)/BD/Sub [完][2016.10][ViVid Strike][01_12] NEW_NODE&amp;amp;Sakurato字幕 繁體 對應BDRIP[Rein/[ReinForce] Vivid Strike! 12 (BDRip 1920x1080 x264 FLAC).NEW_NODE&Sakurato.ass:\n",
      "-->\tTraceback (most recent call last):\n",
      "-->\t  File \"/tmp/ipykernel_34135/4174801234.py\", line 8, in <module>\n",
      "-->\t    data = models.SubtitlePersist.from_file(file,format='ass',exclude_fx=True)\n",
      "-->\t  File \"/home/mix/Documents/SagasuSubs/SagasuSubs/models.py\", line 62, in from_file\n",
      "-->\t    DialogContent(\n",
      "-->\t  File \"pydantic/main.py\", line 406, in pydantic.main.BaseModel.__init__\n",
      "-->\tpydantic.error_wrappers.ValidationError: 1 validation error for DialogContent\n",
      "-->\tbegin\n",
      "-->\t  none is not an allowed value (type=type_error.none.not_allowed)\n"
     ]
    },
    {
     "name": "stderr",
     "output_type": "stream",
     "text": [
      "/home/mix/Documents/SagasuSubs/SagasuSubs/patch.py:59: UserWarning: Failed to parse field f='fontsize',v='' due to ValueError(\"could not convert string to float: ''\"), fallback to None\n",
      "  warn(f\"Failed to parse field {f=!r},{v=!r} due to {e!r}, fallback to None\")\n"
     ]
    },
    {
     "name": "stdout",
     "output_type": "stream",
     "text": [
      "Error occurred during processing file subtitles/subs_list/animation/2017/(2017.4.14)剑姬神圣谭/BD/字幕/Dungeon ni Deai o Motomeru no wa Machigatte Iru Darouka Gaiden Sword Oratoria - 07 (BD 1280x720 x264 AAC).ass:\n",
      "-->\tTraceback (most recent call last):\n",
      "-->\t  File \"/tmp/ipykernel_34135/4174801234.py\", line 8, in <module>\n",
      "-->\t    data = models.SubtitlePersist.from_file(file,format='ass',exclude_fx=True)\n",
      "-->\t  File \"/home/mix/Documents/SagasuSubs/SagasuSubs/models.py\", line 62, in from_file\n",
      "-->\t    DialogContent(\n",
      "-->\t  File \"pydantic/main.py\", line 406, in pydantic.main.BaseModel.__init__\n",
      "-->\tpydantic.error_wrappers.ValidationError: 2 validation errors for DialogContent\n",
      "-->\tbegin\n",
      "-->\t  none is not an allowed value (type=type_error.none.not_allowed)\n",
      "-->\tend\n",
      "-->\t  none is not an allowed value (type=type_error.none.not_allowed)\n",
      "Error occurred during processing file subtitles/subs_list/animation/2017/(2017.4.14)剑姬神圣谭/BD/字幕/Dungeon ni Deai o Motomeru no wa Machigatte Iru Darouka Gaiden Sword Oratoria - 08 (BD 1280x720 x264 AAC).ass:\n",
      "-->\tTraceback (most recent call last):\n",
      "-->\t  File \"/tmp/ipykernel_34135/4174801234.py\", line 8, in <module>\n",
      "-->\t    data = models.SubtitlePersist.from_file(file,format='ass',exclude_fx=True)\n",
      "-->\t  File \"/home/mix/Documents/SagasuSubs/SagasuSubs/models.py\", line 62, in from_file\n",
      "-->\t    DialogContent(\n",
      "-->\t  File \"pydantic/main.py\", line 406, in pydantic.main.BaseModel.__init__\n",
      "-->\tpydantic.error_wrappers.ValidationError: 2 validation errors for DialogContent\n",
      "-->\tbegin\n",
      "-->\t  none is not an allowed value (type=type_error.none.not_allowed)\n",
      "-->\tend\n",
      "-->\t  none is not an allowed value (type=type_error.none.not_allowed)\n",
      "Error occurred during processing file subtitles/subs_list/animation/2017/(2017.4.14)剑姬神圣谭/BD/字幕/Dungeon ni Deai o Motomeru no wa Machigatte Iru Darouka Gaiden Sword Oratoria - 11 (BD 1280x720 x264 AAC).ass:\n",
      "-->\tTraceback (most recent call last):\n",
      "-->\t  File \"/tmp/ipykernel_34135/4174801234.py\", line 8, in <module>\n",
      "-->\t    data = models.SubtitlePersist.from_file(file,format='ass',exclude_fx=True)\n",
      "-->\t  File \"/home/mix/Documents/SagasuSubs/SagasuSubs/models.py\", line 62, in from_file\n",
      "-->\t    DialogContent(\n",
      "-->\t  File \"pydantic/main.py\", line 406, in pydantic.main.BaseModel.__init__\n",
      "-->\tpydantic.error_wrappers.ValidationError: 2 validation errors for DialogContent\n",
      "-->\tbegin\n",
      "-->\t  none is not an allowed value (type=type_error.none.not_allowed)\n",
      "-->\tend\n",
      "-->\t  none is not an allowed value (type=type_error.none.not_allowed)\n",
      "Error occurred during processing file subtitles/subs_list/animation/2017/(2017.4.14)剑姬神圣谭/BD/字幕/Dungeon ni Deai o Motomeru no wa Machigatte Iru Darouka Gaiden Sword Oratoria - 12 (BD 1280x720 x264 AAC).ass:\n",
      "-->\tTraceback (most recent call last):\n",
      "-->\t  File \"/tmp/ipykernel_34135/4174801234.py\", line 8, in <module>\n",
      "-->\t    data = models.SubtitlePersist.from_file(file,format='ass',exclude_fx=True)\n",
      "-->\t  File \"/home/mix/Documents/SagasuSubs/SagasuSubs/models.py\", line 62, in from_file\n",
      "-->\t    DialogContent(\n",
      "-->\t  File \"pydantic/main.py\", line 406, in pydantic.main.BaseModel.__init__\n",
      "-->\tpydantic.error_wrappers.ValidationError: 2 validation errors for DialogContent\n",
      "-->\tbegin\n",
      "-->\t  none is not an allowed value (type=type_error.none.not_allowed)\n",
      "-->\tend\n",
      "-->\t  none is not an allowed value (type=type_error.none.not_allowed)\n"
     ]
    }
   ],
   "source": [
    "progress = tqdm(files)\n",
    "\n",
    "skipped = 0\n",
    "\n",
    "for count,file in enumerate(progress):\n",
    "    progress.set_description(f'{skipped=}, {skipped/(count+1)=:.3%}')\n",
    "    try:\n",
    "        data = models.SubtitlePersist.from_file(file,format='ass',exclude_fx=True)\n",
    "    except Exception:\n",
    "        progress.write(\n",
    "            '\\n-->\\t'.join(\n",
    "                [f'Error occurred during processing file {file}:'] +\n",
    "                format_exc(-3).splitlines()\n",
    "            )\n",
    "        )\n",
    "        skipped += 1\n",
    "        continue\n",
    "\n",
    "    if not (matched := PATH_REGEX.match(str(file))):\n",
    "        progress.write(f'{data.path=} does not have valid regex data, skip')\n",
    "        skipped += 1\n",
    "        continue\n",
    "\n",
    "    if existed_file:=file_crud.read_by_sha1(data.sha1):\n",
    "#         progress.write(f'{data.filename=} conflicted with {existed_file.id=}, {existed_file.filename=} in database, skip')\n",
    "        skipped += 1\n",
    "        continue\n",
    "        \n",
    "    file_model = file_crud.create(dto.FileCreate(\n",
    "        filename=data.filename,\n",
    "        sha1=data.sha1,\n",
    "        path=str(data.path),\n",
    "        series_name=matched.group('name'))\n",
    "    )\n",
    "\n",
    "    dialog_crud.create_bulk(\n",
    "            [\n",
    "                dto.DialogCreate(content=dialog.content,begin=dialog.begin,end=dialog.end,file_id=file_model.id)\n",
    "                for dialog in data.dialogs\n",
    "            ]\n",
    "        )\n",
    "        "
   ]
  },
  {
   "cell_type": "code",
   "execution_count": null,
   "metadata": {},
   "outputs": [],
   "source": []
  }
 ],
 "metadata": {
  "kernelspec": {
   "display_name": "Python 3",
   "language": "python",
   "name": "python3"
  },
  "language_info": {
   "codemirror_mode": {
    "name": "ipython",
    "version": 3
   },
   "file_extension": ".py",
   "mimetype": "text/x-python",
   "name": "python",
   "nbconvert_exporter": "python",
   "pygments_lexer": "ipython3",
   "version": "3.9.6"
  }
 },
 "nbformat": 4,
 "nbformat_minor": 2
}
